<?xml version="1.0" encoding="utf-8"?>
<!-- This URDF was automatically created by SolidWorks to URDF Exporter! Originally created by Stephen Brawner (brawner@gmail.com) 
     Commit Version: 1.5.1-0-g916b5db  Build Version: 1.5.7152.31018
     For more information, please see http://wiki.ros.org/sw_urdf_exporter -->
<robot
  name="robot1_description">
  <link
    name="base_link">
    <inertial>
      <origin
        xyz="-0.015984 -0.00012141 0.15362"
        rpy="0 0 0" />
      <mass
        value="61.482" />
      <inertia
        ixx="1.3604"
        ixy="-0.011898"
        ixz="0.033248"
        iyy="3.3702"
        iyz="-0.00058691"
        izz="3.9879" />
    </inertial>
    <visual>
      <origin
        xyz="0 0 0"
        rpy="0 0 0" />
      <geometry>
        <mesh
          filename="package://robot1_description/meshes/base_link.STL" />
      </geometry>
      <material
        name="">
        <color
          rgba="1 1 1 1" />
      </material>
    </visual>
    <collision>
      <origin
        xyz="0 0 0"
        rpy="0 0 0" />
      <geometry>
        <mesh
          filename="package://robot1_description/meshes/base_link.STL" />
      </geometry>
    </collision>
  </link>
  <link
    name="wheel1_link">
    <inertial>
      <origin
        xyz="2.8205E-08 -0.019536 1.1834E-07"
        rpy="0 0 0" />
      <mass
        value="4.1241" />
      <inertia
        ixx="0.075369"
        ixy="-1.6738E-08"
        ixz="1.9084E-08"
        iyy="0.14899"
        iyz="1.6397E-08"
        izz="0.075369" />
    </inertial>
    <visual>
      <origin
        xyz="0 0 0"
        rpy="0 0 0" />
      <geometry>
        <mesh
          filename="package://robot1_description/meshes/wheel1_link.STL" />
      </geometry>
      <material
        name="">
        <color
          rgba="1 1 1 1" />
      </material>
    </visual>
    <collision>
      <origin
        xyz="0 0 0"
        rpy="0 0 0" />
      <geometry>
        <mesh
          filename="package://robot1_description/meshes/wheel1_link.STL" />
      </geometry>
    </collision>
  </link>
  <joint
    name="wheel1_joint"
    type="continuous">
    <origin
      xyz="0.288 0.3075 0.094"
      rpy="0 0 0" />
    <parent
      link="base_link" />
    <child
      link="wheel1_link" />
    <axis
      xyz="0 1 0" />
  </joint>
  <link
    name="wheel2_link">
    <inertial>
      <origin
        xyz="-9.3542E-10 -0.019537 -2.4308E-08"
        rpy="0 0 0" />
      <mass
        value="4.1241" />
      <inertia
        ixx="0.075369"
        ixy="-9.2393E-10"
        ixz="1.8274E-08"
        iyy="0.14899"
        iyz="2.167E-08"
        izz="0.075369" />
    </inertial>
    <visual>
      <origin
        xyz="0 0 0"
        rpy="0 0 0" />
      <geometry>
        <mesh
          filename="package://robot1_description/meshes/wheel2_link.STL" />
      </geometry>
      <material
        name="">
        <color
          rgba="1 1 1 1" />
      </material>
    </visual>
    <collision>
      <origin
        xyz="0 0 0"
        rpy="0 0 0" />
      <geometry>
        <mesh
          filename="package://robot1_description/meshes/wheel2_link.STL" />
      </geometry>
    </collision>
  </link>
  <joint
    name="wheel2_joint"
    type="continuous">
    <origin
      xyz="-0.288 0.3075 0.094"
      rpy="0 0 0" />
    <parent
      link="base_link" />
    <child
      link="wheel2_link" />
    <axis
      xyz="0 1 0" />
  </joint>
  <link
    name="wheel3_link">
    <inertial>
      <origin
        xyz="-2.8844E-09 0.019537 -2.4145E-08"
        rpy="0 0 0" />
      <mass
        value="4.1241" />
      <inertia
        ixx="0.075369"
        ixy="-7.1906E-10"
        ixz="-1.4728E-08"
        iyy="0.14899"
        iyz="-2.1679E-08"
        izz="0.075369" />
    </inertial>
    <visual>
      <origin
        xyz="0 0 0"
        rpy="0 0 0" />
      <geometry>
        <mesh
          filename="package://robot1_description/meshes/wheel3_link.STL" />
      </geometry>
      <material
        name="">
        <color
          rgba="1 1 1 1" />
      </material>
    </visual>
    <collision>
      <origin
        xyz="0 0 0"
        rpy="0 0 0" />
      <geometry>
        <mesh
          filename="package://robot1_description/meshes/wheel3_link.STL" />
      </geometry>
    </collision>
  </link>
  <joint
    name="wheel3_joint"
    type="continuous">
    <origin
      xyz="0.288 -0.3075 0.094"
      rpy="0 0 0" />
    <parent
      link="base_link" />
    <child
      link="wheel3_link" />
    <axis
      xyz="0 -1 0" />
  </joint>
  <link
    name="wheel4_link">
    <inertial>
      <origin
        xyz="-2.3336E-08 0.019537 4.4299E-09"
        rpy="0 0 0" />
      <mass
        value="4.1241" />
      <inertia
        ixx="0.075369"
        ixy="-1.7968E-08"
        ixz="-1.9023E-08"
        iyy="0.14899"
        iyz="1.2379E-08"
        izz="0.075369" />
    </inertial>
    <visual>
      <origin
        xyz="0 0 0"
        rpy="0 0 0" />
      <geometry>
        <mesh
          filename="package://robot1_description/meshes/wheel4_link.STL" />
      </geometry>
      <material
        name="">
        <color
          rgba="1 1 1 1" />
      </material>
    </visual>
    <collision>
      <origin
        xyz="0 0 0"
        rpy="0 0 0" />
      <geometry>
        <mesh
          filename="package://robot1_description/meshes/wheel4_link.STL" />
      </geometry>
    </collision>
  </link>
  <joint
    name="wheel4_joint"
    type="continuous">
    <origin
      xyz="-0.288 -0.3075 0.094"
      rpy="0 0 0" />
    <parent
      link="base_link" />
    <child
      link="wheel4_link" />
    <axis
      xyz="0 -1 0" />
  </joint>
  <link
    name="column_link">
    <inertial>
      <origin
        xyz="-7.8117E-05 3.5252E-08 0.37224"
        rpy="0 0 0" />
      <mass
        value="5.0542" />
      <inertia
        ixx="0.26842"
        ixy="-1.1974E-08"
        ixz="0.00015689"
        iyy="0.26842"
        iyz="-5.5179E-08"
        izz="0.0051173" />
    </inertial>
    <visual>
      <origin
        xyz="0 0 0"
        rpy="0 0 0" />
      <geometry>
        <mesh
          filename="package://robot1_description/meshes/column_link.STL" />
      </geometry>
      <material
        name="">
        <color
          rgba="1 1 1 1" />
      </material>
    </visual>
    <collision>
      <origin
        xyz="0 0 0"
        rpy="0 0 0" />
      <geometry>
        <mesh
          filename="package://robot1_description/meshes/column_link.STL" />
      </geometry>
    </collision>
  </link>
  <joint
    name="column_joint"
    type="fixed">
    <origin
      xyz="0.388 0 0.31"
      rpy="0 0 0" />
    <parent
      link="base_link" />
    <child
      link="column_link" />
  </joint>
  <link
    name="bevel_link">
    <inertial>
      <origin
        xyz="0.0017035 2.0219E-08 0.024324"
        rpy="0 0 0" />
      <mass
        value="0.59708" />
      <inertia
        ixx="0.0013871"
        ixy="-1.7408E-10"
        ixz="4.1626E-05"
        iyy="0.0011567"
        iyz="-2.5096E-10"
        izz="0.0018827" />
    </inertial>
    <visual>
      <origin
        xyz="0 0 0"
        rpy="0 0 0" />
      <geometry>
        <mesh
          filename="package://robot1_description/meshes/bevel_link.STL" />
      </geometry>
      <material
        name="">
        <color
          rgba="1 1 1 1" />
      </material>
    </visual>
    <collision>
      <origin
        xyz="0 0 0"
        rpy="0 0 0" />
      <geometry>
        <mesh
          filename="package://robot1_description/meshes/bevel_link.STL" />
      </geometry>
    </collision>
  </link>
  <joint
    name="bevel_joint"
    type="fixed">
    <origin
      xyz="0.02894 0 0.76592"
      rpy="0 0 0" />
    <parent
      link="column_link" />
    <child
      link="bevel_link" />
  </joint>
  <link
    name="imu_link">
    <inertial>
      <origin
        xyz="0.00085309 2.7756E-17 0.0069478"
        rpy="0 0 0" />
      <mass
        value="0.0289" />
      <inertia
        ixx="5.8426E-06"
        ixy="-5.2902E-22"
        ixz="5.0592E-07"
        iyy="5.1238E-06"
        iyz="1.4634E-22"
        izz="9.9009E-06" />
    </inertial>
    <visual>
      <origin
        xyz="0 0 0"
        rpy="0 0 0" />
      <geometry>
        <mesh
          filename="package://robot1_description/meshes/imu_link.STL" />
      </geometry>
      <material
        name="">
        <color
          rgba="1 1 1 1" />
      </material>
    </visual>
    <collision>
      <origin
        xyz="0 0 0"
        rpy="0 0 0" />
      <geometry>
        <mesh
          filename="package://robot1_description/meshes/imu_link.STL" />
      </geometry>
    </collision>
  </link>
  <joint
    name="imu_joint"
    type="fixed">
    <origin
      xyz="0.041475 0 -0.019198"
      rpy="0 0 0" />
    <parent
      link="bevel_link" />
    <child
      link="imu_link" />
  </joint>
  <link
    name="camera_link">
    <inertial>
      <origin
        xyz="-0.021158 -2.7756E-17 0.01999"
        rpy="0 0 0" />
      <mass
        value="0.25858" />
      <inertia
        ixx="0.00054733"
        ixy="-1.4454E-19"
        ixz="2.3977E-06"
        iyy="7.5957E-05"
        iyz="2.8085E-20"
        izz="0.00056624" />
    </inertial>
    <visual>
      <origin
        xyz="0 0 0"
        rpy="0 0 0" />
      <geometry>
        <mesh
          filename="package://robot1_description/meshes/camera_link.STL" />
      </geometry>
      <material
        name="">
        <color
          rgba="1 1 1 1" />
      </material>
    </visual>
    <collision>
      <origin
        xyz="0 0 0"
        rpy="0 0 0" />
      <geometry>
        <mesh
          filename="package://robot1_description/meshes/camera_link.STL" />
      </geometry>
    </collision>
  </link>
  <joint
    name="camera_joint"
    type="fixed">
    <origin
      xyz="0.066821 0 0.012678"
      rpy="0 0 0" />
    <parent
      link="bevel_link" />
    <child
      link="camera_link" />
  </joint>
  <link
    name="3dlaser_link">
    <inertial>
      <origin
        xyz="0.0040217 -2.7756E-17 0.032754"
        rpy="0 0 0" />
      <mass
        value="0.59289" />
      <inertia
        ixx="0.00064754"
        ixy="-4.5948E-20"
        ixz="1.5916E-05"
        iyy="0.00064558"
        iyz="2.6123E-20"
        izz="0.00077521" />
    </inertial>
    <visual>
      <origin
        xyz="0 0 0"
        rpy="0 0 0" />
      <geometry>
        <mesh
          filename="package://robot1_description/meshes/3dlaser_link.STL" />
      </geometry>
      <material
        name="">
        <color
          rgba="1 1 1 1" />
      </material>
    </visual>
    <collision>
      <origin
        xyz="0 0 0"
        rpy="0 0 0" />
      <geometry>
        <mesh
          filename="package://robot1_description/meshes/3dlaser_link.STL" />
      </geometry>
    </collision>
  </link>
  <joint
    name="3dlaser_joint"
    type="fixed">
    <origin
      xyz="0.022797 0 0.070749"
      rpy="0 0 0" />
    <parent
      link="bevel_link" />
    <child
      link="3dlaser_link" />
  </joint>

<gazebo reference="wheel1_link">
	<material>Gazebo/Black</material>
</gazebo>

<gazebo reference="wheel2_link">
	<material>Gazebo/Black</material>
</gazebo>

<gazebo reference="wheel3_link">
	<material>Gazebo/Black</material>
</gazebo>

<gazebo reference="wheel4_link">
	<material>Gazebo/Black</material>
</gazebo>

<gazebo reference="imu_link">
	<material>Gazebo/Red</material>
</gazebo>

<gazebo reference="camera_link">
	<material>Gazebo/Yellow</material>
</gazebo>

<gazebo reference="base_link">
	<material>Gazebo/Orange</material>
</gazebo>

<gazebo reference="column_link">
	<material>Gazebo/White</material>
</gazebo>

<gazebo reference="bevel_link">
	<material>Gazebo/White</material>
</gazebo>

<gazebo reference="3dlaser_link">
	<material>Gazebo/Blue</material>
</gazebo>
</robot>
