<?xml version="1.0"?>
<robot xmlns:xacro="http://www.ros.org/wiki/xacro" 
 	xmlns:sensor="http://playerstage.sourceforge.net/gazebo/xmlschema/#sensor"
    	xmlns:controller="http://playerstage.sourceforge.net/gazebo/xmlschema/#controller"
    	xmlns:interface="http://playerstage.sourceforge.net/gazebo/xmlschema/#interface"
	name="robot1_xacro">
	<xacro:property name="length_wheel" value="0.15" />
	<xacro:property name="radius_wheel" value="0.25" />
	<xacro:property name="camera_link" value="0.05" /> 
	<xacro:macro name="default_inertial" params="mass">
               <inertial>
                       <mass value="${mass}" />
                       <inertia ixx="1.0" ixy="0.0" ixz="0.0"
                                iyy="1.0" iyz="0.0"
                                izz="1.0" />
               </inertial>
	</xacro:macro>
 	<xacro:include filename="$(find robot1_description)/urdf/robot.gazebo" />
 	<!-- <xacro:include filename="$(find robot1_description)/urdf/vlp16.xacro" /> -->
	<link name="base_footprint">
   		<visual>
			<geometry>
      				<box size="0.001 0.001 0.001"/>
     			</geometry>
			<origin rpy="0 0 0" xyz="0 0 0"/>
   		</visual>
		<xacro:default_inertial mass="0.0001"/>
 	</link>
 
	<gazebo reference="base_footprint">
		<material>Gazebo/Green</material>
		<turnGravityOff>false</turnGravityOff>
	</gazebo>

	<joint name="base_footprint_joint" type="fixed">
		<origin xyz="0 0 0" />
		<parent link="base_footprint" />
		<child link="base_link" />
	</joint>
	<link name="base_link">
   		<visual>
			<geometry>
      				<box size="0.45 1.002 0.3"/>
     			</geometry>
			<origin rpy="0 0 1.5707" xyz="0 0 0"/>
			<material name="white">
				<color rgba="1 1 1 1"/>
			</material>
   		</visual>
		<collision>
			<geometry>
       				<box size="0.45 1.002 0.3"/>
			</geometry>
		</collision>
		<xacro:default_inertial mass="10"/>
 	</link>
 	<link name="wheel_1">
   		<visual>
     			<geometry>
       				<cylinder length="${length_wheel}" radius="${radius_wheel}"/>
     			</geometry>
			<!-- <origin rpy="0 1.5 0" xyz="0.1 0.1 0"/> -->
			<origin rpy="0 0 0" xyz="0 0 0"/>
   			<material name="black">
				<color rgba="0 0 0 1"/>
			</material>
		</visual>
		<collision>
			<geometry>
       				<cylinder length="${length_wheel}" radius="${radius_wheel}"/>
			</geometry>
		</collision>
		<xacro:default_inertial mass="1"/>
 	</link>
 	<link name="wheel_2">
   		<visual>
     			<geometry>
       				<cylinder length="${length_wheel}" radius="${radius_wheel}"/>
     			</geometry>
			<!-- <origin rpy="0 1.5 0" xyz="-0.1 0.1 0"/> -->
			<origin rpy="0 0 0" xyz="0 0 0"/>
   			<material name="black"/>
   		</visual>
		<collision>
			<geometry>
       				<cylinder length="${length_wheel}" radius="${radius_wheel}"/>
			</geometry>
		</collision>
		<xacro:default_inertial mass="1"/>

 	</link>
 	<link name="wheel_3">
   		<visual>
     			<geometry>
       				<cylinder length="${length_wheel}" radius="${radius_wheel}"/>
     			</geometry>
			<!-- <origin rpy="0 1.5 0" xyz="0.1 -0.1 0"/> -->

			<origin rpy="0 0 0" xyz="0 0 0"/>
   			<material name="black"/>
   		</visual>
		<collision>
			<geometry>
       				<cylinder length="${length_wheel}" radius="${radius_wheel}"/>
			</geometry>
		</collision>
		<xacro:default_inertial mass="1"/>
 	</link>
 	<link name="wheel_4">
   		<visual>
     			<geometry>
       				<cylinder length="${length_wheel}" radius="${radius_wheel}"/>
     			</geometry>
		<!--	<origin rpy="0 1.5 0" xyz="-0.1 -0.1 0"/> -->
			<origin rpy="0 0 0" xyz="0 0 0" />
   			<material name="black"/>
   		</visual>
		<collision>
			<geometry>
       				<cylinder length="${length_wheel}" radius="${radius_wheel}"/>
			</geometry>
		</collision>
		<xacro:default_inertial mass="1"/>

 	</link>
 <joint name="base_to_wheel1" type="continuous">
   <parent link="base_link"/>
   <child link="wheel_1"/>
   <origin rpy="-1.5707 0 0" xyz="0.225 0.501 0"/>
   <axis xyz="0 0 1" />
 </joint>
 <joint name="base_to_wheel2" type="continuous">
   <axis xyz="0 0 1" />
   <anchor xyz="0 0 0" />
   <limit effort="100" velocity="100" />
   <parent link="base_link"/>
   <child link="wheel_2"/>
   <origin rpy="-1.5707 0 0" xyz="-0.225 0.501 0"/>
</joint>
 <joint name="base_to_wheel3" type="continuous">
   <parent link="base_link"/>
   <axis xyz="0 0 1" />
   <child link="wheel_3"/>
   <origin rpy="-1.5707 0 0" xyz="0.225 -0.501 0"/>
 </joint>
 <joint name="base_to_wheel4" type="continuous">
   <parent link="base_link"/>
   <axis xyz="0 0 1" />
   <child link="wheel_4"/>
   <origin rpy="-1.5707 0 0" xyz="-0.225 -0.501 0"/>
 </joint>
  <!-- Colum joint -->
  <joint name="colum_joint" type="fixed">
    <axis xyz="0 1 0" />
    <origin xyz="0.3 0 0.55" rpy="0 0 0"/>
    <parent link="base_link"/>
    <child link="colum_link"/>
  </joint>
  <!-- Colum -->
  <link name="colum_link">
    <collision>
      <origin xyz="0 0 0" rpy="0 0 0"/>
      <geometry>
	<box size="0.05 0.05 0.8"/>
      </geometry>
    </collision>
    <visual>
      <origin xyz="0 0 0" rpy="0 0 0"/>
      <geometry>
	<box size="0.05 0.05 0.8"/>
      </geometry>
	<material name="white">
	<color rgba="1 1 1 1"/>
	</material>
    </visual>
  </link>


  <!-- Camera joint 1 -->
  <joint name="camera_joint" type="fixed">
    <axis xyz="0 1 0" />
    <origin xyz="0.3 0 0.984" rpy="0 0.2349 0"/>
    <parent link="base_link"/>
    <child link="camera_link"/>
  </joint>
  <!-- Camera -->
  <link name="camera_link">
    <collision>
      <origin xyz="0 0 0" rpy="0 0 0"/>
      <geometry>
	<box size="0.05 0.05 0.05"/>
      </geometry>
    </collision>
    <visual>
      <origin xyz="0 0 0" rpy="0 0 0"/>
      <geometry>
	<box size="0.05 0.05 0.05"/>
      </geometry>
      <material name="red">
	<color rgba="1 0 0 1"/>
      </material>
    </visual>
    <inertial>
      <mass value="1e-5" />
      <origin xyz="0 0 0" rpy="0 0 0"/>
      <inertia ixx="1e-6" ixy="0" ixz="0" iyy="1e-6" iyz="0" izz="1e-6" />
    </inertial>
  </link>



  <!-- imu joint -->
  <joint name="imu_joint" type="fixed">
    <axis xyz="0 1 0" />
    <origin xyz="0.3 0 0.984" rpy="0 0.349 0"/>
    <parent link="base_link"/>
    <child link="imu_link"/>
  </joint>
  <!-- imu -->
  <link name="imu_link">
    <collision>
      <origin xyz="0 0 0" rpy="0 0 0"/>
      <geometry>
	<box size="0.05 0.05 0.05"/>
      </geometry>
    </collision>
    <visual>
      <origin xyz="0 0 0" rpy="0 0 0"/>
      <geometry>
	<box size="0.05 0.05 0.05"/>
      </geometry>
      <material name="red">
	<color rgba="1 0 0 1"/>
      </material>
    </visual>
    <inertial>
      <mass value="1e-5" />
      <origin xyz="0 0 0" rpy="0 0 0"/>
      <inertia ixx="1e-6" ixy="0" ixz="0" iyy="1e-6" iyz="0" izz="1e-6" />
    </inertial>
  </link>
  <!-- VLP-16 -->
  <!-- <xacro:include filename="$(find velodyne_description)/urdf/VLP-16.urdf.xacro"/>
  <VLP-16 parent="base_link">
    <origin xyz="0.3 0 1.0085" rpy="0 0.349 0" />
  </VLP-16> -->
  <!-- VLP-16 lidar -->
	  <xacro:include filename="$(find velodyne_description)/urdf/VLP-16.urdf.xacro"/>
	  <VLP-16 parent="base_link" name="velodyne" topic="/velodyne_points" hz="10" samples="1024" gpu="true" lasers="16" max_range="100">
	    <origin xyz="0.3 0 1.0085" rpy="0 0.2349 0" />
	  </VLP-16>
</robot>
